Workbook

Sheet Dashboard
A1: Refer to "Procurement-Dashboard.html" file.

Sheet Code
A1: Project Metadata Title | B1: Project Metadata Values | C1: Project Metadata Data Type | E1: Discipline Code | F1: Discipline Description | H1: Criticality Code | I1: Criticality | K1: Status Code | L1: Package Status | N1: Category Code | O1: Item Category | Q1: Error Code | R1: Error Description | S1: Severity | T1: Group | U1: Kind | V1: Trigger Check
A2: Project Title | B2: TWRP C3B2 | C2: Text | E2: A | F2: Architecture | H2: 0 | I2: Not Applicable | K2: NS | L2: Not Start | N2: BSW | O2: Building Service Work Package | Q2: V-01 | R2: Rows inside the data range with a blank Package Title are skipped | S2: info | T2: Structure / Rows | U2: system | V2: Row in range has no Package Title
A3: Project Code | B3: C3B2 | C3: Text | E3: B | F3: Building Services | H3: 1 | I3: Factory In-house Quality Control | K3: MR | L3: Requisition in Progress | N3: CAB | O3: Cable | Q3: V-02 | R3: Value is a number but not a real Excel date | S3: error | T3: Dates | U3: data | V3: Date field is a number but not in the Excel date range (40000–70000)
A4: Client | B4: PUB | C4: Text | E4: C | F4: Civil | H4: 2 | I4: Third Party Inspection | K4: VI | L4: Pending Vendor Approval | N4: CTL | O4: Cable Tray and Ladder | Q4: V-03 | R4: Text value cannot be read as a date | S4: error | T4: Dates | U4: data | V4: Date field is text that cannot be parsed
A5: Consultant | B5: Jacobs | C5: Text | E5: D | F5: Design Management | H5: 3 | I5: Witness Point | K5: PP | L5: Pending PO Confirmation | N5: CWP | O5: Construction Work Package | Q5: V-04 | R5: Value is not numeric | S5: error | T5: Values / Numeric | U5: data | V5: Quantity or Lead Time is non-numeric
A6: Dashboard Title | B6: Procurement Package Plan | C6: Text | E6: E | F6: Electrical | H6: 4 | I6: FAT Record Submission Only | K6: PO | L6: PO Issued, Prepare Vendor Data Submission | N6: DCS | O6: Design Consultancy Service | Q6: V-05 | R6: Criticality must be one of the listed values; empty count is reported separately | S6: error / warning | T6: Criticality | U6: data | V6: Criticality not in the Code sheet (code or description); aggregate blank count
A7: Project Start Date | B7: 46100 | C7: Date | E7: G | F7: Geotechnical | K7: VDA | L7: Pending Vendor Data Approval | N7: EBK | O7: EICA Bulk | Q7: V-06 | R7: Discipline not found in the Code sheet list | S7: warning | T7: Discipline | U7: data | V7: Discipline not in the Code sheet list
A8: Header Row | B8: 1 | C8: Int | E8: HS | F8: Environmental, Health, Safety & Security | K8: FAB | L8: Fabrication in Progress | N8: EPN | O8: EICA Panels | Q8: V-07 | R8: Status not found in the Code sheet list | S8: error | T8: Status | U8: data | V8: Status not in the Code sheet list (code or description)
A9: List End Row | B9: 300 | C9: Int | E9: I | F9: Instrument, Control & Automation (ICA) | K9: FAT | L9: FAT Completed | N9: EEQ | O9: Electrical Equipment | Q9: V-08 | R9: Stage plan dates are out of sequence | S9: warning | T9: Dates / Stages | U9: data | V9: Stage plan out of sequence (e.g., MR Plan > PO Plan)
A10: S No. | B10: Column-A | C10: Int | E10: IM | F10: Information Management/IT | K10: DEL | L10: Delivered | N10: EQP | O10: Equipment Package | Q10: V-09 | R10: Actual date entered but the Plan is empty | S10: warning | T10: Dates / Stages | U10: data | V10: Actual date present but the matching Plan is empty
A11: Discipline | B11: Column-B | C11: Text | E11: K | F11: Construction Management | K11: RI | L11: Receive Inspection Done | N11: IEQ | O11: ICA Equipment | Q11: V-10 | R11: Actual date is later than today | S11: warning | T11: Dates / Stages | U11: data | V11: Actual date later than today (the as-of date)
A12: Package Title | B12: Column-C | C12: Text | E12: M | F12: Mechanical | N12: IPN | O12: ICA Panel | Q12: V-11 | R12: Duplicate Package No. — appears N times | S12: warning | T12: Identity | U12: data | V12: Duplicate Package No.
A13: Package No. | B13: Column-D | C13: Text | E13: PI | F13: Piping | N13: INS | O13: Instrument | Q13: V-12 | R13: Same engineer written different ways — counted as N separate people | S13: warning | T13: Engineer | U13: data | V13: Same engineer written differently (whitespace / slash-spacing variants)
A14: Item Category | B14: Column-E | C14: Text | E14: PR | F14: Process | N14: MMI | O14: Misc. Mech Item | Q14: V-13 | R14: Rows after List End Row contain a Package Title but are excluded | S14: warning | T14: Structure / Rows | U14: system | V14: PPP rows with a Title beyond List End Row
A15: Area | B15: Column-F | C15: Text | E15: PC | F15: Project Controls | N15: PBK | O15: Piping Bulk | Q15: V-14 | R15: Lead time missing on N packages (X%) | S15: warning | T15: Lead time | U15: data | V15: Lead time missing on more than 50% of packages
A16: Equipment Tags | B16: Column-G | C16: Text | E16: PM | F16: Project Management | N16: PSP | O16: Piping SP | Q16: V-15 | R16: Header Row, List End Row, Project Start Date or Data Type issue | S16: error / warning | T16: Config / Code sheet | U16: system | V16: Code-sheet config / Data-Type mismatch (Header / List End / Start / Type)
A17: Package Notes | B17: Column-H | C17: Text | E17: Q | F17: Quantity Survey/Estimating | N17: REQ | O17: Rotating Equipment | Q17: V-16 | R17: Column C has no Data Type values — fell back to built-in | S17: warning | T17: Config / Code sheet | U17: system | V17: Code sheet column C empty (no Data Types)
A18: Criticality | B18: Column-I | C18: Text | E18: S | F18: Structural | N18: SEQ | O18: Static Equipment | Q18: V-17 | R18: Item Category not found in the Code sheet list (reference only) | S18: info | T18: Category | U18: data | V18: Item Category not in the Code sheet list
A19: Quantity | B19: Column-J | C19: Number | E19: W | F19: Procurement, Contract | N19: VAL | O19: Valve | Q19: V-18 | R19: Lookup block not found in row 1 | S19: warning | T19: Config / Lookup | U19: system | V19: A lookup block absent from Code row 1, or its code column empty
A20: Estimate Lead Time | B20: Column-K | C20: Int | E20: Z | F20: General (non-specific) | N20: PSV | O20: Pressure Vessel | Q20: V-19 | R20: Header Row has no value in the Package Title column | S20: warning | T20: Config / Code sheet | U20: system | V20: PPP Header Row cell at the title column is blank
A21: Package Status | B21: Column-L | C21: Text | Q21: V-20 | R21: Expected N data rows but only M had content | S21: warning | T21: Structure / Rows | U21: system | V21: Expected data rows exceed actual parsed rows
A22: Supplier | B22: Column-M | C22: Text | Q22: V-21 | R22: Rule code has no row in the Code sheet Error table | S22: warning | T22: Config / Workbook | U22: system | V22: A rule code has no row in the Code!Q:R Error table
A23: Design Engineer | B23: Column-N | C23: Text | Q23: V-22 | R23: Lookup code column is empty — values cannot be cross-checked | S23: warning | T23: Config / Lookup | U23: system | V23: A lookup block's CODE column is empty while its description column has values
A24: Buyer | B24: Column-O | C24: Text | Q24: V-23 | R24: No Actual dates entered in any stage for any package | S24: warning | T24: Progress / Execution | U24: data | V24: Execution progress = 0 (no Actual dates in any stage, any package)
A25: Project Engineer | B25: Column-P | C25: Text | Q25: V-24 | R25: Package has no Design Engineer | S25: warning | T25: Engineer | U25: data | V25: Engineer unassigned / blank
A26: MR Plan Date | B26: Column-Q | C26: Date | Q26: V-25 | R26: MR Plan entered for few packages while PO Plan present for many | S26: warning | T26: Dates / Stages | U26: data | V26: Plan-date inconsistency (MR Plan sparse vs PO Plan present)
A27: MR Forecast Date | B27: Column-R | C27: Date
A28: MR Actual Date | B28: Column-S | C28: Date
A29: PO Plan Date | B29: Column-T | C29: Date
A30: PO Forecast Date | B30: Column-U | C30: Date
A31: PO Actual Date | B31: Column-V | C31: Date
A32: VD Approval Plan Date | B32: Column-W | C32: Date
A33: VD Approval Forecast Date | B33: Column-X | C33: Date
A34: VD Approval Actual Date | B34: Column-Y | C34: Date
A35: FAT Plan Date | B35: Column-Z | C35: Date
A36: FAT Forecast Date | B36: Column-AA | C36: Date
A37: FAT Actual Date | B37: Column-AB | C37: Date
A38: ROS Plan Date | B38: Column-AC | C38: Date
... A40: ROS Actual Date | B40: Column-AE | C40: Date

Sheet PPP
A1: S/No. (A1) | B1: Discipline (A2) | C1: Package Title (A3) | D1: Package No. (A4) | E1: Item Category (A5) | F1: Area (A6) | G1: Equipment Tags (A7) | H1: Package Notes (A8) | I1: Criticality (A9) | J1: Quantity (Nos.) (A10) | K1: Estimate Lead Time (Days) (A11) | L1: Package Status (A12) | M1: Supplier (A13) | N1: Design Engineer (B1) | O1: Buyer (B2) | P1: PE (B3) | Q1: MR Plan Date (C1) | R1: MR Forecast Date (C2) | S1: MR Actual Date (C3) | T1: PO Plan Date (D1) | U1: PO Forecast Date (D2) | V1: PO Actual Date (D3) | W1: VD Approval Plan Date (E1) | X1: VD Approval Forecast Date (E2) | Y1: VD Approval Actual Date (E3) | Z1: FAT Plan Date (F1) | AA1: FAT Forecast Date (F2) | AB1: FAT Actual Date (F3) | AC1: ROS Plan Date (G1) | AD1: ROS Forecast Date (G2) | AE1: ROS Actual Date (G3)
A2: 1 | B2: Design Management | C2: CSA Consultant | D2: ="MR-"&_xlfn.XLOOKUP(B2, Code!$F:$F, Code!$E:$E, "NA")&"-"&TEXT(A2,"0000") -> MR-D-0001 | E2: Design Consultancy Service | F2: All | I2: Not Applicable | K2: 30 | L2: PO Issued, Prepare Vendor Data Submission | N2: Mark | Q2: 46218 | T2: 46249 | V2: 46295 | AC2: 46280
A3: 2 | B3: Design Management | C3: HAZOP and ALMOP Consultant | D3: ="MR-"&_xlfn.XLOOKUP(B3, Code!$F:$F, Code!$E:$E, "NA")&"-"&TEXT(A3,"0000") -> MR-D-0002 | E3: Design Consultancy Service | F3: All | H3: [2026/09/11] SO suggested to engage PureTach. | I3: Not Applicable | K3: 30 | L3: Not Start | N3: Kenny | Q3: 46267 | T3: 46327 | AC3: 46402
A4: 3 | B4: Design Management | C4: M&E Consultant (Building Service) | D4: ="MR-"&_xlfn.XLOOKUP(B4, Code!$F:$F, Code!$E:$E, "NA")&"-"&TEXT(A4,"0000") -> MR-D-0003 | E4: Design Consultancy Service | F4: All | I4: Not Applicable | K4: 30 | L4: Not Start | N4: Fadil | Q4: 46157 | T4: 46218 | U4: 46341 | AC4: 46249
A5: 4 | B5: Design Management | C5: Mechanical Consultant | D5: ="MR-"&_xlfn.XLOOKUP(B5, Code!$F:$F, Code!$E:$E, "NA")&"-"&TEXT(A5,"0000") -> MR-D-0004 | E5: Design Consultancy Service | F5: All | I5: Not Applicable | K5: 30 | L5: Not Start | N5: Franklin | Q5: 46540 | T5: 46600 | AC5: 46631
A6: 7 | B6: Project Management | C6: Tank PVC Lining Installation Contractor | D6: ="MR-"&_xlfn.XLOOKUP(B6, Code!$F:$F, Code!$E:$E, "NA")&"-"&TEXT(A6,"0000") -> MR-PM-0007 | E6: Construction Work Package | F6: All | H6: [2026/10/05] PO# 22151 | I6: Not Applicable | K6: 30 | L6: PO Issued, Prepare Vendor Data Submission | M6: VORTEX | N6: Mark | Q6: 46189 | T6: 46249 | V6: 46248 | AC6: 46280
A7: 8 | B7: Project Management | C7: Mechanical Installation Contractor | D7: ="MR-"&_xlfn.XLOOKUP(B7, Code!$F:$F, Code!$E:$E, "NA")&"-"&TEXT(A7,"0000") -> MR-PM-0008 | E7: Construction Work Package | F7: All | I7: Not Applicable | K7: 30 | L7: Not Start | N7: TBC | Q7: 46328 | T7: 46388 | AC7: 46419
A8: 9 | B8: Project Management | C8: Electrical Installation Contractor | D8: ="MR-"&_xlfn.XLOOKUP(B8, Code!$F:$F, Code!$E:$E, "NA")&"-"&TEXT(A8,"0000") -> MR-PM-0009 | E8: Construction Work Package | F8: All | H8: to consider direct sub contracting. | I8: Not Applicable | K8: 30 | L8: Not Start | N8: Ammar | Q8: 46328 | T8: 46388 | AC8: 46419
A9: 128 | B9: Project Management | C9: ICA Installation Contractor | D9: ="MR-"&_xlfn.XLOOKUP(B9, Code!$F:$F, Code!$E:$E, "NA")&"-"&TEXT(A9,"0000") -> MR-PM-0128 | E9: Construction Work Package | F9: All | I9: Not Applicable | K9: 30 | L9: Not Start | N9: Ricarte | Q9: 46328 | T9: 46388 | AC9: 46419
A10: 10 | B10: Project Management | C10: Structure Steel Fabricator | D10: ="MR-"&_xlfn.XLOOKUP(B10, Code!$F:$F, Code!$E:$E, "NA")&"-"&TEXT(A10,"0000") -> MR-PM-0010 | E10: Construction Work Package | F10: All | I10: Not Applicable | K10: 30 | L10: Not Start | N10: TBC | Q10: 46267 | T10: 46327
A11: 11 | B11: Project Management | C11: Structure Steel Installation Contractor | D11: ="MR-"&_xlfn.XLOOKUP(B11, Code!$F:$F, Code!$E:$E, "NA")&"-"&TEXT(A11,"0000") -> MR-PM-0011 | E11: Construction Work Package | F11: All | I11: Not Applicable | K11: 30 | L11: Not Start | N11: TBC | Q11: 45994 | T11: 46419
A12: 12 | B12: Project Management | C12: Concrete Work Contractor | D12: ="MR-"&_xlfn.XLOOKUP(B12, Code!$F:$F, Code!$E:$E, "NA")&"-"&TEXT(A12,"0000") -> MR-PM-0012 | E12: Construction Work Package | F12: All | I12: Not Applicable | K12: 30 | L12: Not Start | N12: TBC | Q12: 46267 | T12: 46327
A13: 13 | B13: Civil | C13: GI grating | D13: ="MR-"&_xlfn.XLOOKUP(B13, Code!$F:$F, Code!$E:$E, "NA")&"-"&TEXT(A13,"0000") -> MR-C-0013 | E13: Construction Work Package | F13: All | I13: Not Applicable | K13: 30 | L13: Not Start | N13: TBC | Q13: 46387 | T13: 46447
A14: 14 | B14: Structural | C14: Aluminium Railing, Ladder and Cover | D14: ="MR-"&_xlfn.XLOOKUP(B14, Code!$F:$F, Code!$E:$E, "NA")&"-"&TEXT(A14,"0000") -> MR-S-0014 | E14: Construction Work Package | F14: All | I14: Not Applicable | K14: 30 | L14: Not Start | N14: TBC | Q14: 46479 | T14: 46539
A15: 20 | B15: Mechanical | C15: Ejector | D15: ="MR-"&_xlfn.XLOOKUP(B15, Code!$F:$F, Code!$E:$E, "NA")&"-"&TEXT(A15,"0000") -> MR-M-0020 | E15: Static Equipment | F15: WIL23 | G15: WIL23 - ILM2 MBR Filtrate Air Ejector 1~9 (TBC) | I15: FAT Record Submission Only | J15: 9 | K15: 60 | L15: Requisition in Progress | N15: Fadhli | Q15: 46274 | T15: =Q15+60 -> 46334 | W15: =T15+60 -> 46394 | Z15: =AC15-30 -> 46364 | AC15: =K15+T15 -> 46394
A16: 26 | B16: Mechanical | C16: CFD analysis/ hydraulic modelling / surge analysis | D16: ="MR-"&_xlfn.XLOOKUP(B16, Code!$F:$F, Code!$E:$E, "NA")&"-"&TEXT(A16,"0000") -> MR-M-0026 | E16: Design Consultancy Service | I16: FAT Record Submission Only | K16: 30 | L16: Requisition in Progress | N16: Kenny/Franklin | Q16: 46235 | T16: 46295 | U16: 46341 | W16: =T16+60 -> 46355 | Z16: =AC16-30 -> 46295 | AC16: 46325
A17: 46 | B17: Piping | C17: Pressure Relief Valve | D17: ="MR-"&_xlfn.XLOOKUP(B17, Code!$F:$F, Code!$E:$E, "NA")&"-"&TEXT(A17,"0000") -> MR-PI-0046 | E17: Valve | I17: FAT Record Submission Only | K17: 30 | L17: Requisition in Progress | N17: Fadhli | Q17: 46235 | T17: 46386 | W17: =T17+60 -> 46446 | Z17: =AC17-30 -> 46386 | AC17: =K17+T17 -> 46416
A18: 47 | B18: Piping | C18: Pressure Reducing Valve - Metal | D18: ="MR-"&_xlfn.XLOOKUP(B18, Code!$F:$F, Code!$E:$E, "NA")&"-"&TEXT(A18,"0000") -> MR-PI-0047 | E18: Valve | I18: FAT Record Submission Only | K18: 30 | L18: Requisition in Progress | N18: Fadhli | Q18: 46235 | T18: 46386 | W18: =T18+60 -> 46446 | Z18: =AC18-30 -> 46386 | AC18: =K18+T18 -> 46416
A19: 48 | B19: Piping | C19: Pressure Sustaning Valve - Metal | D19: ="MR-"&_xlfn.XLOOKUP(B19, Code!$F:$F, Code!$E:$E, "NA")&"-"&TEXT(A19,"0000") -> MR-PI-0048 | E19: Valve | I19: FAT Record Submission Only | K19: 30 | L19: Requisition in Progress | N19: Fadhli | Q19: 46235 | T19: 46386 | W19: =T19+60 -> 46446 | Z19: =AC19-30 -> 46386 | AC19: =K19+T19 -> 46416
A20: 49 | B20: Piping | C20: Plastic Valve (Ball, Check, Back Pressure) | D20: ="MR-"&_xlfn.XLOOKUP(B20, Code!$F:$F, Code!$E:$E, "NA")&"-"&TEXT(A20,"0000") -> MR-PI-0049 | E20: Valve | I20: FAT Record Submission Only | K20: 30 | L20: Requisition in Progress | N20: Fadhli | Q20: 46235 | T20: 46386 | W20: =T20+60 -> 46446 | Z20: =AC20-30 -> 46386 | AC20: =K20+T20 -> 46416
A21: 50 | B21: Piping | C21: Condensate Drain | D21: ="MR-"&_xlfn.XLOOKUP(B21, Code!$F:$F, Code!$E:$E, "NA")&"-"&TEXT(A21,"0000") -> MR-PI-0050 | E21: Valve | I21: FAT Record Submission Only | K21: 30 | L21: Not Start | N21: TBC | Q21: 46235 | T21: 46356 | W21: =T21+60 -> 46416 | Z21: =AC21-30 -> 46356 | AC21: =K21+T21 -> 46386
A22: 52 | B22: Piping | C22: Stainless Steel Piping | D22: ="MR-"&_xlfn.XLOOKUP(B22, Code!$F:$F, Code!$E:$E, "NA")&"-"&TEXT(A22,"0000") -> MR-PI-0052 | E22: Piping Bulk | G22: Cast-in piping may be ordered separately. | I22: FAT Record Submission Only | K22: 60 | L22: Not Start | N22: Dilip/Siva | Q22: 46417 | T22: 46447 | AC22: 46507
A23: 53 | B23: Piping | C23: CSEL Piping | D23: ="MR-"&_xlfn.XLOOKUP(B23, Code!$F:$F, Code!$E:$E, "NA")&"-"&TEXT(A23,"0000") -> MR-PI-0053 | E23: Piping Bulk | G23: Cast-in piping may be ordered separately. | I23: FAT Record Submission Only | K23: 60 | L23: Not Start | N23: Dilip/Siva | Q23: 46417 | T23: 46447 | AC23: 46507
A24: 54 | B24: Piping | C24: DI and DIPU Piping | D24: ="MR-"&_xlfn.XLOOKUP(B24, Code!$F:$F, Code!$E:$E, "NA")&"-"&TEXT(A24,"0000") -> MR-PI-0054 | E24: Piping Bulk | G24: Cast-in piping may be ordered separately. | I24: FAT Record Submission Only | K24: 60 | L24: Not Start | N24: Dilip/Siva | Q24: 46299 | T24: 46359 | AC24: 46419
A25: 55 | B25: Piping | C25: FRP Piping | D25: ="MR-"&_xlfn.XLOOKUP(B25, Code!$F:$F, Code!$E:$E, "NA")&"-"&TEXT(A25,"0000") -> MR-PI-0055 | E25: Piping Bulk | G25: Cast-in piping may be ordered separately. | I25: FAT Record Submission Only | K25: 60 | L25: Not Start | N25: Dilip/Siva | Q25: 46299 | T25: 46359 | AC25: 46419
A26: 56 | B26: Piping | C26: PVC and cPVC Piping | D26: ="MR-"&_xlfn.XLOOKUP(B26, Code!$F:$F, Code!$E:$E, "NA")&"-"&TEXT(A26,"0000") -> MR-PI-0056 | E26: Piping Bulk | G26: Cast-in piping may be ordered separately. | I26: FAT Record Submission Only | K26: 60 | L26: Not Start | N26: Dilip/Siva | Q26: 46419 | T26: 46479 | AC26: 46539
A27: 57 | B27: Piping | C27: HDPE Piping | D27: ="MR-"&_xlfn.XLOOKUP(B27, Code!$F:$F, Code!$E:$E, "NA")&"-"&TEXT(A27,"0000") -> MR-PI-0057 | E27: Piping Bulk | G27: Cast-in piping may be ordered separately. | I27: FAT Record Submission Only | K27: 60 | L27: Not Start | N27: Dilip/Siva | Q27: 46299 | T27: 46359 | AC27: 46419
A28: 58 | B28: Piping | C28: Chemical Valve Box | D28: ="MR-"&_xlfn.XLOOKUP(B28, Code!$F:$F, Code!$E:$E, "NA")&"-"&TEXT(A28,"0000") -> MR-PI-0058 | E28: Piping SP | I28: FAT Record Submission Only | K28: 60 | L28: Not Start | N28: Dilip/Siva | Q28: 46299 | T28: 46479 | AC28: 46539
A29: 59 | B29: Piping | C29: Piping Gasket | D29: ="MR-"&_xlfn.XLOOKUP(B29, Code!$F:$F, Code!$E:$E, "NA")&"-"&TEXT(A29,"0000") -> MR-PI-0059 | E29: Piping Bulk | I29: FAT Record Submission Only | K29: 60 | L29: Not Start | N29: Dilip/Siva | Q29: 46299 | T29: 46359 | AC29: 46419
A30: 60 | B30: Piping | C30: Piping Standard/Primary Support | D30: ="MR-"&_xlfn.XLOOKUP(B30, Code!$F:$F, Code!$E:$E, "NA")&"-"&TEXT(A30,"0000") -> MR-PI-0060 | E30: Piping Bulk | I30: FAT Record Submission Only | K30: 60 | L30: Not Start | N30: Dilip/Siva | Q30: 46299 | T30: 46359 | AC30: 46419
A31: 61 | B31: Piping | C31: Piping Bolts and Nuts | D31: ="MR-"&_xlfn.XLOOKUP(B31, Code!$F:$F, Code!$E:$E, "NA")&"-"&TEXT(A31,"0000") -> MR-PI-0061 | E31: Piping Bulk | I31: FAT Record Submission Only | K31: 60 | L31: Not Start | N31: Dilip/Siva | Q31: 46299 | T31: 46359 | AC31: 46419
A32: 62 | B32: Piping | C32: Piping SP Items (to be separated) | D32: ="MR-"&_xlfn.XLOOKUP(B32, Code!$F:$F, Code!$E:$E, "NA")&"-"&TEXT(A32,"0000") -> MR-PI-0062 | E32: Piping SP | I32: FAT Record Submission Only | K32: 60 | L32: Not Start | N32: Dilip/Siva | Q32: 46299 | T32: 46359 | AC32: 46419
A33: 63 | B33: Piping | C33: Piping Secondary Support (MS) | D33: ="MR-"&_xlfn.XLOOKUP(B33, Code!$F:$F, Code!$E:$E, "NA")&"-"&TEXT(A33,"0000") -> MR-PI-0063 | E33: Piping Bulk | I33: FAT Record Submission Only | K33: 60 | L33: Not Start | N33: TBC | Q33: 46342 | T33: 46402 | AC33: 46462
A34: 64 | B34: Piping | C34: Piping Secondary Support (Unistrut) | D34: ="MR-"&_xlfn.XLOOKUP(B34, Code!$F:$F, Code!$E:$E, "NA")&"-"&TEXT(A34,"0000") -> MR-PI-0064 | E34: Piping Bulk | I34: FAT Record Submission Only | K34: 60 | L34: Not Start | N34: Dilip/Siva | Q34: 46299 | T34: 46359 | AC34: 46419
A35: 69 | B35: Electrical | C35: VDB | D35: ="MR-"&_xlfn.XLOOKUP(B35, Code!$F:$F, Code!$E:$E, "NA")&"-"&TEXT(A35,"0000") -> MR-E-0069 | E35: EICA Panels | H35: Valve Sub-DB(160A) - 5 nos Valve Sub-DB(80A) - 11 nos Valve Sub-DB(63A) - 30 nos Local DB - FP Equipment - 5 nos | J35: 51 | K35: 140 | M35: Sunlight | N35: Ammar | Q35: 46322 | T35: 46382 | W35: =T35+60 -> 46442 | Z35: =AC35-30 -> 46492 | AC35: 46522
A36: 73 | B36: Electrical | C36: MV, LV, and Earthing Cable | D36: ="MR-"&_xlfn.XLOOKUP(B36, Code!$F:$F, Code!$E:$E, "NA")&"-"&TEXT(A36,"0000") -> MR-E-0073 | E36: Cable | I36: FAT Record Submission Only | K36: 84 | L36: Pending Vendor Approval | M36: Tai Jie | N36: Ammar | Q36: 46289 | T36: 46349 | W36: =T36+60 -> 46409 | Z36: =AC36-30 -> 46403 | AC36: 46433
A37: 74 | B37: Electrical | C37: Lighting and Small Power | D37: ="MR-"&_xlfn.XLOOKUP(B37, Code!$F:$F, Code!$E:$E, "NA")&"-"&TEXT(A37,"0000") -> MR-E-0074 | E37: EICA Bulk | H37: Main Breaker 80A TPN MCCB 65KA c/w SHT TRIP - Sub breaker 39×1P 50kA MCB/ 4×3P 50kA MCB - Outgoing breaker 39×2P 40A 30mA RCCB/ 4×4P 40A 100mA RCD | I37: FAT Record Submission Only | J37: 33 | K37: 60 | L37: Requisition in Progress | N37: Ammar | Q37: 46346 | T37: 46407 | W37: =T37+60 -> 46467 | Z37: =AC37-30 -> 46446 | AC37: 46476
A38: 78 | B38: Instrument, Control & Automation (ICA) | C38: LCP Panel | D38: ="MR-"&_xlfn.XLOOKUP(B38, Code!$F:$F, Code!$E:$E, "NA")&"-"&TEXT(A38,"0000") -> MR-I-0078 | E38: EICA Panels | F38: WIL23 | G38: WIL23-LCP-CA-0101 | H38: To confirm LCP panel list Process: 16 nos. Non-process: 1 nos. | I38: FAT Record Submission Only | J38: =16+1 -> 17 | K38: 70 | L38: Not Start | N38: Ricarte | Q38: 46362 | T38: 46422 | W38: =T38+60 -> 46482 | Z38: =AC38-30 -> 46462 | AC38: 46492
A39: 79 | B39: Instrument, Control & Automation (ICA) | C39: ICA Field UPS DB | D39: ="MR-"&_xlfn.XLOOKUP(B39, Code!$F:$F, Code!$E:$E, "NA")&"-"&TEXT(A39,"0000") -> MR-I-0079 | E39: EICA Panels | F39: WIL13 WIL23 | G39: WIL23-UPS-0002 to 0004 WIL13-UPS-0001, 0002 | H39: To confirm UPS panel list | I39: FAT Record Submission Only | J39: =8 -> 8 | K39: 84 | L39: Not Start | N39: Ricarte | Q39: 46501 | T39: 46561 | W39: =T39+60 -> 46621 | Z39: =AC39-30 -> 46615 | AC39: 46645
A40: 80 | B40: Instrument, Control & Automation (ICA) | C40: ICA Junction Box | D40: ="MR-"&_xlfn.XLOOKUP(B40, Code!$F:$F, Code!$E:$E, "NA")&"-"&TEXT(A40,"0000") -> MR-I-0080 | E40: EICA Panels | G40: Refer to panel master list and panel GA | I40: FAT Record Submission Only | K40: 56 | L40: Not Start | N40: Ricarte | Q40: 46345 | T40: 46405 | W40: =T40+60 -> 46465 | Z40: =AC40-30 -> 46431 | AC40: 46461
...
